
load model from training phase 1
Traceback (most recent call last):
  File "/home/clannad/anaconda3/envs/py310pytorch/lib/python3.10/site-packages/transformers/configuration_utils.py", line 672, in _get_config_dict
    resolved_config_file = cached_file(
  File "/home/clannad/anaconda3/envs/py310pytorch/lib/python3.10/site-packages/transformers/utils/hub.py", line 417, in cached_file
    resolved_file = hf_hub_download(
  File "/home/clannad/anaconda3/envs/py310pytorch/lib/python3.10/site-packages/huggingface_hub/utils/_validators.py", line 110, in _inner_fn
    validate_repo_id(arg_value)
  File "/home/clannad/anaconda3/envs/py310pytorch/lib/python3.10/site-packages/huggingface_hub/utils/_validators.py", line 158, in validate_repo_id
    raise HFValidationError(
huggingface_hub.utils._validators.HFValidationError: Repo id must be in the form 'repo_name' or 'namespace/repo_name': 'Results/random-20-2023/gpt2-xsum-chat/model_directory1'. Use `repo_type` argument if needed.
During handling of the above exception, another exception occurred:
Traceback (most recent call last):
  File "/home/clannad/Dropbox/0WaterMark/WatermarkPreliminary/main.py", line 262, in <module>
    model = GPT2LMHeadModel.from_pretrained(folder+'/model_directory'+str(1))
  File "/home/clannad/anaconda3/envs/py310pytorch/lib/python3.10/site-packages/transformers/modeling_utils.py", line 2325, in from_pretrained
    config, model_kwargs = cls.config_class.from_pretrained(
  File "/home/clannad/anaconda3/envs/py310pytorch/lib/python3.10/site-packages/transformers/configuration_utils.py", line 590, in from_pretrained
    config_dict, kwargs = cls.get_config_dict(pretrained_model_name_or_path, **kwargs)
  File "/home/clannad/anaconda3/envs/py310pytorch/lib/python3.10/site-packages/transformers/configuration_utils.py", line 617, in get_config_dict
    config_dict, kwargs = cls._get_config_dict(pretrained_model_name_or_path, **kwargs)
  File "/home/clannad/anaconda3/envs/py310pytorch/lib/python3.10/site-packages/transformers/configuration_utils.py", line 693, in _get_config_dict
    raise EnvironmentError(
OSError: Can't load the configuration of 'Results/random-20-2023/gpt2-xsum-chat/model_directory1'. If you were trying to load it from 'https://huggingface.co/models', make sure you don't have a local directory with the same name. Otherwise, make sure 'Results/random-20-2023/gpt2-xsum-chat/model_directory1' is the correct path to a directory containing a config.json file